Workbook

Sheet Project Instructions
A1: PR. 2 Analyzer
A2: Topics: - Conditional Formatting - WHAT IF Analysis - Linear Regression (Using Data Analysis Toolpak) - Data Analysis Feature (Descriptive Stats, Regression, Histogram) - Data Storytelling - Add Symbols or Arrows in Custom Formatting - Create Timestamp - Find High-Value Customers using Groupby(), index(), and match() combination - Advanced Descriptive Analytics - Pivot Table with Dashboard - Creating bar charts - Creating line charts - Creating pie charts Main Tasks: 1. Apply conditional formatting to highlight top 10 customers based on total purchase. 2. Perform WHAT IF Analysis to see impact of changing discount on total profit. 3. Use Data Analysis Toolpak to run Linear Regression (Profit vs Sales). 4. Use 'Descriptive Statistics' from Analysis Toolpak on the dataset. 5. Add up/down arrows on monthly sales growth. 6. Create a timestamp column using NOW(). 7. Identify high-value customers using index(), match(), and filters. 8. Create Pivot Table to analyze total sales by region and product. 9. Create bar, line, and pie charts to visualize KPIs. 10. Summarize insights using a dashboard. Deliverable: Complete the given worksheet by applying the required formulas in respective sheets.

Sheet Dataset
A1: Customer_ID | B1: Customer_Name | C1: Region | D1: Product_Category | E1: Sales | F1: Quantity | G1: Discount | H1: Order_Date | I1: Profit | J1: Customer Total Purchase | K1: Top 10 Customer | L1: Gross Sales (pre-discount) | M1: Scenario Sales | N1: Scenario Profit | O1: Profit Margin % | P1: Order Month | Q1: Customer Tier | R1: Report Timestamp | T1: WHAT-IF ANALYSIS – DISCOUNT vs TOTAL PROFIT | AA1: JUMP TO (click)
A2: CUST019 | B2: James Davis | C2: West | D2: Books | E2: 1036.09 | F2: 4 | G2: 0.2 | H2: 45392 | I2: 331.55 | J2: =SUMIFS($E$2:$E$201,$A$2:$A$201,A2) -> 4640.11 | K2: =IF(INDEX('Pivot Table'!$N$5:$N$34,MATCH(A2,'Pivot Table'!$I$5:$I$34,0))<=10,"Top 10","") | L2: =ROUND(E2/(1-G2),2) -> 1295.11 | M2: =ROUND(L2*(1-$U$3),2) -> 1165.6 | N2: =ROUND(M2-(E2-I2),2) -> 461.06 | O2: =I2/E2 -> 0.32000116 | P2: =DATE(YEAR(H2),MONTH(H2),1) -> 45383 | Q2: =IF(J2>='Pivot Table'!$R$4,"High Value","Standard") -> Standard | R2: =NOW() -> 46304.64
A3: CUST012 | B3: Robert Anderson | C3: West | D3: Clothing | E3: 1101.28 | F3: 3 | G3: 0.2 | H3: 45393 | I3: 440.51 | J3: =SUMIFS($E$2:$E$201,$A$2:$A$201,A3) -> 8339 | K3: =IF(INDEX('Pivot Table'!$N$5:$N$34,MATCH(A3,'Pivot Table'!$I$5:$I$34,0))<=10,"Top 10","") -> Top 10 | L3: =ROUND(E3/(1-G3),2) -> 1376.6 | M3: =ROUND(L3*(1-$U$3),2) -> 1238.94 | N3: =ROUND(M3-(E3-I3),2) -> 578.17 | O3: =I3/E3 -> 0.39999818 | P3: =DATE(YEAR(H3),MONTH(H3),1) -> 45383 | Q3: =IF(J3>='Pivot Table'!$R$4,"High Value","Standard") -> High Value | R3: =NOW() -> 46304.64 | T3: Scenario discount (enter) | U3: 0.1 | AA3: 1. What-If Analysis
A4: CUST017 | B4: James Taylor | C4: East | D4: Books | E4: 713.34 | F4: 17 | G4: 0 | H4: 45396 | I4: 285.34 | J4: =SUMIFS($E$2:$E$201,$A$2:$A$201,A4) -> 3419.2 | K4: =IF(INDEX('Pivot Table'!$N$5:$N$34,MATCH(A4,'Pivot Table'!$I$5:$I$34,0))<=10,"Top 10","") | L4: =ROUND(E4/(1-G4),2) -> 713.34 | M4: =ROUND(L4*(1-$U$3),2) -> 642.01 | N4: =ROUND(M4-(E4-I4),2) -> 214.01 | O4: =I4/E4 -> 0.40000561 | P4: =DATE(YEAR(H4),MONTH(H4),1) -> 45383 | Q4: =IF(J4>='Pivot Table'!$R$4,"High Value","Standard") -> Standard | R4: =NOW() -> 46304.64 | T4: Metric | U4: Current | V4: Scenario | W4: Change | X4: % Change | AA4: 2. Descriptive Statistics
A5: CUST005 | B5: Robert Anderson | C5: South | D5: Electronics | E5: 760.93 | F5: 4 | G5: 0.15 | H5: 45396 | I5: 161.7 | J5: =SUMIFS($E$2:$E$201,$A$2:$A$201,A5) -> 6666.13 | K5: =IF(INDEX('Pivot Table'!$N$5:$N$34,MATCH(A5,'Pivot Table'!$I$5:$I$34,0))<=10,"Top 10","") | L5: =ROUND(E5/(1-G5),2) -> 895.21 | M5: =ROUND(L5*(1-$U$3),2) -> 805.69 | N5: =ROUND(M5-(E5-I5),2) -> 206.46 | O5: =I5/E5 -> 0.21250312 | P5: =DATE(YEAR(H5),MONTH(H5),1) -> 45383 | Q5: =IF(J5>='Pivot Table'!$R$4,"High Value","Standard") -> Standard | R5: =NOW() -> 46304.64 | T5: Average discount | U5: =AVERAGE($G$2:$G$201) -> 0.09725 | V5: =U3 -> 0.1 | W5: =V5-U5 -> 0.00275 | AA5: 3. Regression (ToolPak format)
A6: CUST030 | B6: James Wilson | C6: North | D6: Books | E6: 847 | F6: 12 | G6: 0.2 | H6: 45397 | I6: 271.04 | J6: =SUMIFS($E$2:$E$201,$A$2:$A$201,A6) -> 7928.71 | K6: =IF(INDEX('Pivot Table'!$N$5:$N$34,MATCH(A6,'Pivot Table'!$I$5:$I$34,0))<=10,"Top 10","") -> Top 10 | L6: =ROUND(E6/(1-G6),2) -> 1058.75 | M6: =ROUND(L6*(1-$U$3),2) -> 952.88 | N6: =ROUND(M6-(E6-I6),2) -> 376.92 | O6: =I6/E6 -> 0.32 | P6: =DATE(YEAR(H6),MONTH(H6),1) -> 45383 | Q6: =IF(J6>='Pivot Table'!$R$4,"High Value","Standard") -> Standard | R6: =NOW() -> 46304.64 | T6: Total sales | U6: =SUM($E$2:$E$201) -> 195217.76 | V6: =SUM(M2:M201) -> 196224.59 | W6: =V6-U6 -> 1006.83 | X6: =W6/U6 -> 0.0051574713 | AA6: 4. Residual Output
A7: CUST007 | B7: Michael Anderson | C7: North | D7: Furniture | E7: 965.64 | F7: 8 | G7: 0.1 | H7: 45398 | I7: 304.18 | J7: =SUMIFS($E$2:$E$201,$A$2:$A$201,A7) -> 9941.88 | K7: =IF(INDEX('Pivot Table'!$N$5:$N$34,MATCH(A7,'Pivot Table'!$I$5:$I$34,0))<=10,"Top 10","") -> Top 10 | L7: =ROUND(E7/(1-G7),2) -> 1072.93 | M7: =ROUND(L7*(1-$U$3),2) -> 965.64 | N7: =ROUND(M7-(E7-I7),2) -> 304.18 | O7: =I7/E7 -> 0.31500352 | P7: =DATE(YEAR(H7),MONTH(H7),1) -> 45383 | Q7: =IF(J7>='Pivot Table'!$R$4,"High Value","Standard") -> High Value | R7: =NOW() -> 46304.64 | T7: Total cost (held constant) | U7: =SUM($E$2:$E$201)-SUM($I$2:$I$201) -> 126930.75 | V7: =U7 -> 126930.75 | W7: =V7-U7 -> 0 | X7: =IF(U7=0,0,W7/U7) -> 0 | AA7: 5. Histogram
A8: CUST001 | B8: Linda Wilson | C8: West | D8: Electronics | E8: 1317.53 | F8: 12 | G8: 0.05 | H8: 45398 | I8: 312.91 | J8: =SUMIFS($E$2:$E$201,$A$2:$A$201,A8) -> 6549.55 | K8: =IF(INDEX('Pivot Table'!$N$5:$N$34,MATCH(A8,'Pivot Table'!$I$5:$I$34,0))<=10,"Top 10","") | L8: =ROUND(E8/(1-G8),2) -> 1386.87 | M8: =ROUND(L8*(1-$U$3),2) -> 1248.18 | N8: =ROUND(M8-(E8-I8),2) -> 243.56 | O8: =I8/E8 -> 0.23749744 | P8: =DATE(YEAR(H8),MONTH(H8),1) -> 45383 | Q8: =IF(J8>='Pivot Table'!$R$4,"High Value","Standard") -> Standard | R8: =NOW() -> 46304.64 | T8: TOTAL PROFIT | U8: =SUM($I$2:$I$201) -> 68287.01 | V8: =SUM(N2:N201) -> 69293.84 | W8: =V8-U8 -> 1006.83 | X8: =W8/U8 -> 0.014744093
A9: CUST026 | B9: Mary Davis | C9: East | D9: Furniture | E9: 1074.47 | F9: 6 | G9: 0.2 | H9: 45401 | I9: 300.85 | J9: =SUMIFS($E$2:$E$201,$A$2:$A$201,A9) -> 9371.81 | K9: =IF(INDEX('Pivot Table'!$N$5:$N$34,MATCH(A9,'Pivot Table'!$I$5:$I$34,0))<=10,"Top 10","") -> Top 10 | L9: =ROUND(E9/(1-G9),2) -> 1343.09 | M9: =ROUND(L9*(1-$U$3),2) -> 1208.78 | N9: =ROUND(M9-(E9-I9),2) -> 435.16 | O9: =I9/E9 -> 0.27999851 | P9: =DATE(YEAR(H9),MONTH(H9),1) -> 45383 | Q9: =IF(J9>='Pivot Table'!$R$4,"High Value","Standard") -> High Value | R9: =NOW() -> 46304.64 | T9: Profit margin | U9: =U8/U6 -> 0.34979917 | V9: =V8/V6 -> 0.35313535 | W9: =V9-U9 -> 0.0033361859
A10: CUST009 | B10: Linda Jackson | C10: Central | D10: Books | E10: 501.54 | F10: 11 | G10: 0.05 | H10: 45401 | I10: 190.59 | J10: =SUMIFS($E$2:$E$201,$A$2:$A$201,A10) -> 6505.2 | K10: =IF(INDEX('Pivot Table'!$N$5:$N$34,MATCH(A10,'Pivot Table'!$I$5:$I$34,0))<=10,"Top 10","") | L10: =ROUND(E10/(1-G10),2) -> 527.94 | M10: =ROUND(L10*(1-$U$3),2) -> 475.15 | N10: =ROUND(M10-(E10-I10),2) -> 164.2 | O10: =I10/E10 -> 0.38000957 | P10: =DATE(YEAR(H10),MONTH(H10),1) -> 45383 | Q10: =IF(J10>='Pivot Table'!$R$4,"High Value","Standard") -> Standard | R10: =NOW() -> 46304.64
A11: CUST010 | B11: David Thomas | C11: Central | D11: Clothing | E11: 737.31 | F11: 2 | G11: 0.05 | H11: 45401 | I11: 350.22 | J11: =SUMIFS($E$2:$E$201,$A$2:$A$201,A11) -> 4259.22 | K11: =IF(INDEX('Pivot Table'!$N$5:$N$34,MATCH(A11,'Pivot Table'!$I$5:$I$34,0))<=10,"Top 10","") | L11: =ROUND(E11/(1-G11),2) -> 776.12 | M11: =ROUND(L11*(1-$U$3),2) -> 698.51 | N11: =ROUND(M11-(E11-I11),2) -> 311.42 | O11: =I11/E11 -> 0.47499695 | P11: =DATE(YEAR(H11),MONTH(H11),1) -> 45383 | Q11: =IF(J11>='Pivot Table'!$R$4,"High Value","Standard") -> Standard | R11: =NOW() -> 46304.64 | T11: Target total profit (enter) | U11: 80000
A12: CUST014 | B12: Emma Davis | C12: West | D12: Office Supplies | E12: 1572.82 | F12: 6 | G12: 0.05 | H12: 45402 | I12: 672.38 | J12: =SUMIFS($E$2:$E$201,$A$2:$A$201,A12) -> 6729.89 | K12: =IF(INDEX('Pivot Table'!$N$5:$N$34,MATCH(A12,'Pivot Table'!$I$5:$I$34,0))<=10,"Top 10","") | L12: =ROUND(E12/(1-G12),2) -> 1655.6 | M12: =ROUND(L12*(1-$U$3),2) -> 1490.04 | N12: =ROUND(M12-(E12-I12),2) -> 589.6 | O12: =I12/E12 -> 0.42749965 | P12: =DATE(YEAR(H12),MONTH(H12),1) -> 45383 | Q12: =IF(J12>='Pivot Table'!$R$4,"High Value","Standard") -> Standard | R12: =NOW() -> 46304.64 | T12: Discount needed to hit target (Goal Seek) | U12: =IF(1-(U11+U7)/SUM(L2:L201)<0,"Not achievable",1-(U11+U7)/SUM(L2:L201)) -> 0.050895058
A13: CUST014 | B13: David Thomas | C13: Central | D13: Books | E13: 1343.13 | F13: 14 | G13: 0.15 | H13: 45404 | I13: 456.66 | J13: =SUMIFS($E$2:$E$201,$A$2:$A$201,A13) -> 6729.89 | K13: =IF(INDEX('Pivot Table'!$N$5:$N$34,MATCH(A13,'Pivot Table'!$I$5:$I$34,0))<=10,"Top 10","") | L13: =ROUND(E13/(1-G13),2) -> 1580.15 | M13: =ROUND(L13*(1-$U$3),2) -> 1422.14 | N13: =ROUND(M13-(E13-I13),2) -> 535.67 | O13: =I13/E13 -> 0.33999687 | P13: =DATE(YEAR(H13),MONTH(H13),1) -> 45383 | Q13: =IF(J13>='Pivot Table'!$R$4,"High Value","Standard") -> Standard | R13: =NOW() -> 46304.64
A14: CUST007 | B14: Michael Anderson | C14: Central | D14: Books | E14: 1191.58 | F14: 14 | G14: 0.05 | H14: 45406 | I14: 452.8 | J14: =SUMIFS($E$2:$E$201,$A$2:$A$201,A14) -> 9941.88 | K14: =IF(INDEX('Pivot Table'!$N$5:$N$34,MATCH(A14,'Pivot Table'!$I$5:$I$34,0))<=10,"Top 10","") -> Top 10 | L14: =ROUND(E14/(1-G14),2) -> 1254.29 | M14: =ROUND(L14*(1-$U$3),2) -> 1128.86 | N14: =ROUND(M14-(E14-I14),2) -> 390.08 | O14: =I14/E14 -> 0.37999966 | P14: =DATE(YEAR(H14),MONTH(H14),1) -> 45383 | Q14: =IF(J14>='Pivot Table'!$R$4,"High Value","Standard") -> High Value | R14: =NOW() -> 46304.64 | T14: SENSITIVITY TABLE – impact of changing the discount
A15: CUST023 | B15: Robert Anderson | C15: West | D15: Furniture | E15: 822.28 | F15: 7 | G15: 0.05 | H15: 45406 | I15: 273.41 | J15: =SUMIFS($E$2:$E$201,$A$2:$A$201,A15) -> 5913.68 | K15: =IF(INDEX('Pivot Table'!$N$5:$N$34,MATCH(A15,'Pivot Table'!$I$5:$I$34,0))<=10,"Top 10","") | L15: =ROUND(E15/(1-G15),2) -> 865.56 | M15: =ROUND(L15*(1-$U$3),2) -> 779 | N15: =ROUND(M15-(E15-I15),2) -> 230.13 | O15: =I15/E15 -> 0.33250231 | P15: =DATE(YEAR(H15),MONTH(H15),1) -> 45383 | Q15: =IF(J15>='Pivot Table'!$R$4,"High Value","Standard") -> Standard | R15: =NOW() -> 46304.64 | T15: Discount | U15: Total Sales | V15: Total Profit | W15: Profit Margin | X15: Δ Profit vs Current | Y15: % Δ Profit
A16: CUST029 | B16: David Smith | C16: North | D16: Furniture | E16: 521.67 | F16: 15 | G16: 0.15 | H16: 45409 | I16: 155.2 | J16: =SUMIFS($E$2:$E$201,$A$2:$A$201,A16) -> 5779.05 | K16: =IF(INDEX('Pivot Table'!$N$5:$N$34,MATCH(A16,'Pivot Table'!$I$5:$I$34,0))<=10,"Top 10","") | L16: =ROUND(E16/(1-G16),2) -> 613.73 | M16: =ROUND(L16*(1-$U$3),2) -> 552.36 | N16: =ROUND(M16-(E16-I16),2) -> 185.89 | O16: =I16/E16 -> 0.29750609 | P16: =DATE(YEAR(H16),MONTH(H16),1) -> 45383 | Q16: =IF(J16>='Pivot Table'!$R$4,"High Value","Standard") -> Standard | R16: =NOW() -> 46304.64 | T16: 0 | U16: =SUM($L$2:$L$201)*(1-T16) -> 218027.26 | V16: =U16-$U$7 -> 91096.51 | W16: =V16/U16 -> 0.41782165 | X16: =V16-$U$8 -> 22809.5 | Y16: =X16/$U$8 -> 0.334024
A17: CUST005 | B17: Sarah Anderson | C17: South | D17: Electronics | E17: 1502.93 | F17: 14 | G17: 0.2 | H17: 45410 | I17: 300.59 | J17: =SUMIFS($E$2:$E$201,$A$2:$A$201,A17) -> 6666.13 | K17: =IF(INDEX('Pivot Table'!$N$5:$N$34,MATCH(A17,'Pivot Table'!$I$5:$I$34,0))<=10,"Top 10","") | L17: =ROUND(E17/(1-G17),2) -> 1878.66 | M17: =ROUND(L17*(1-$U$3),2) -> 1690.79 | N17: =ROUND(M17-(E17-I17),2) -> 488.45 | O17: =I17/E17 -> 0.20000266 | P17: =DATE(YEAR(H17),MONTH(H17),1) -> 45383 | Q17: =IF(J17>='Pivot Table'!$R$4,"High Value","Standard") -> Standard | R17: =NOW() -> 46304.64 | T17: 0.05 | U17: =SUM($L$2:$L$201)*(1-T17) -> 207125.9 | V17: =U17-$U$7 -> 80195.147 | W17: =V17/U17 -> 0.38718069 | X17: =V17-$U$8 -> 11908.137 | Y17: =X17/$U$8 -> 0.17438363
A18: CUST008 | B18: Robert Anderson | C18: South | D18: Books | E18: 877.58 | F18: 10 | G18: 0.15 | H18: 45411 | I18: 298.38 | J18: =SUMIFS($E$2:$E$201,$A$2:$A$201,A18) -> 9760.8 | K18: =IF(INDEX('Pivot Table'!$N$5:$N$34,MATCH(A18,'Pivot Table'!$I$5:$I$34,0))<=10,"Top 10","") -> Top 10 | L18: =ROUND(E18/(1-G18),2) -> 1032.45 | M18: =ROUND(L18*(1-$U$3),2) -> 929.21 | N18: =ROUND(M18-(E18-I18),2) -> 350.01 | O18: =I18/E18 -> 0.34000319 | P18: =DATE(YEAR(H18),MONTH(H18),1) -> 45383 | Q18: =IF(J18>='Pivot Table'!$R$4,"High Value","Standard") -> High Value | R18: =NOW() -> 46304.64 | T18: 0.1 | U18: =SUM($L$2:$L$201)*(1-T18) -> 196224.53 | V18: =U18-$U$7 -> 69293.784 | W18: =V18/U18 -> 0.35313517 | X18: =V18-$U$8 -> 1006.774 | Y18: =X18/$U$8 -> 0.014743273
A19: CUST001 | B19: Lisa Thomas | C19: West | D19: Books | E19: 636.7 | F19: 4 | G19: 0.2 | H19: 45411 | I19: 203.74 | J19: =SUMIFS($E$2:$E$201,$A$2:$A$201,A19) -> 6549.55 | K19: =IF(INDEX('Pivot Table'!$N$5:$N$34,MATCH(A19,'Pivot Table'!$I$5:$I$34,0))<=10,"Top 10","") | L19: =ROUND(E19/(1-G19),2) -> 795.88 | M19: =ROUND(L19*(1-$U$3),2) -> 716.29 | N19: =ROUND(M19-(E19-I19),2) -> 283.33 | O19: =I19/E19 -> 0.31999372 | P19: =DATE(YEAR(H19),MONTH(H19),1) -> 45383 | Q19: =IF(J19>='Pivot Table'!$R$4,"High Value","Standard") -> Standard | R19: =NOW() -> 46304.64 | T19: 0.15 | U19: =SUM($L$2:$L$201)*(1-T19) -> 185323.17 | V19: =U19-$U$7 -> 58392.421 | W19: =V19/U19 -> 0.3150843 | X19: =V19-$U$8 -> -9894.589 | Y19: =X19/$U$8 -> -0.14489709
A20: CUST006 | B20: Mary Jackson | C20: West | D20: Books | E20: 1506.14 | F20: 13 | G20: 0.2 | H20: 45412 | I20: 481.96 | J20: =SUMIFS($E$2:$E$201,$A$2:$A$201,A20) -> 2699.75 | K20: =IF(INDEX('Pivot Table'!$N$5:$N$34,MATCH(A20,'Pivot Table'!$I$5:$I$34,0))<=10,"Top 10","") | L20: =ROUND(E20/(1-G20),2) -> 1882.68 | M20: =ROUND(L20*(1-$U$3),2) -> 1694.41 | N20: =ROUND(M20-(E20-I20),2) -> 670.23 | O20: =I20/E20 -> 0.31999681 | P20: =DATE(YEAR(H20),MONTH(H20),1) -> 45383 | Q20: =IF(J20>='Pivot Table'!$R$4,"High Value","Standard") -> Standard | R20: =NOW() -> 46304.64 | T20: 0.2 | U20: =SUM($L$2:$L$201)*(1-T20) -> 174421.81 | V20: =U20-$U$7 -> 47491.058 | W20: =V20/U20 -> 0.27227707 | X20: =V20-$U$8 -> -20795.952 | Y20: =X20/$U$8 -> -0.30453745
A21: CUST026 | B21: Mary Davis | C21: Central | D21: Electronics | E21: 645.02 | F21: 4 | G21: 0 | H21: 45414 | I21: 161.26 | J21: =SUMIFS($E$2:$E$201,$A$2:$A$201,A21) -> 9371.81 | K21: =IF(INDEX('Pivot Table'!$N$5:$N$34,MATCH(A21,'Pivot Table'!$I$5:$I$34,0))<=10,"Top 10","") -> Top 10 | L21: =ROUND(E21/(1-G21),2) -> 645.02 | M21: =ROUND(L21*(1-$U$3),2) -> 580.52 | N21: =ROUND(M21-(E21-I21),2) -> 96.76 | O21: =I21/E21 -> 0.25000775 | P21: =DATE(YEAR(H21),MONTH(H21),1) -> 45413 | Q21: =IF(J21>='Pivot Table'!$R$4,"High Value","Standard") -> High Value | R21: =NOW() -> 46304.64 | T21: 0.25 | U21: =SUM($L$2:$L$201)*(1-T21) -> 163520.45 | V21: =U21-$U$7 -> 36589.695 | W21: =V21/U21 -> 0.2237622 | X21: =V21-$U$8 -> -31697.315 | Y21: =X21/$U$8 -> -0.46417781
A22: CUST007 | B22: Lisa Davis | C22: South | D22: Clothing | E22: 953.3 | F22: 11 | G22: 0 | H22: 45415 | I22: 476.65 | J22: =SUMIFS($E$2:$E$201,$A$2:$A$201,A22) -> 9941.88 | K22: =IF(INDEX('Pivot Table'!$N$5:$N$34,MATCH(A22,'Pivot Table'!$I$5:$I$34,0))<=10,"Top 10","") -> Top 10 | L22: =ROUND(E22/(1-G22),2) -> 953.3 | M22: =ROUND(L22*(1-$U$3),2) -> 857.97 | N22: =ROUND(M22-(E22-I22),2) -> 381.32 | O22: =I22/E22 -> 0.5 | P22: =DATE(YEAR(H22),MONTH(H22),1) -> 45413 | Q22: =IF(J22>='Pivot Table'!$R$4,"High Value","Standard") -> High Value | R22: =NOW() -> 46304.64 | T22: =U3 -> 0.1 | U22: =SUM($L$2:$L$201)*(1-T22) -> 196224.53 | V22: =U22-$U$7 -> 69293.784 | W22: =V22/U22 -> 0.35313517 | X22: =V22-$U$8 -> 1006.774 | Y22: =X22/$U$8 -> 0.014743273
A23: CUST022 | B23: Robert Anderson | C23: North | D23: Electronics | E23: 388.56 | F23: 14 | G23: 0.15 | H23: 45416 | I23: 82.57 | J23: =SUMIFS($E$2:$E$201,$A$2:$A$201,A23) -> 4418.28 | K23: =IF(INDEX('Pivot Table'!$N$5:$N$34,MATCH(A23,'Pivot Table'!$I$5:$I$34,0))<=10,"Top 10","") | L23: =ROUND(E23/(1-G23),2) -> 457.13 | M23: =ROUND(L23*(1-$U$3),2) -> 411.42 | N23: =ROUND(M23-(E23-I23),2) -> 105.43 | O23: =I23/E23 -> 0.21250257 | P23: =DATE(YEAR(H23),MONTH(H23),1) -> 45413 | Q23: =IF(J23>='Pivot Table'!$R$4,"High Value","Standard") -> Standard | R23: =NOW() -> 46304.64
A24: CUST019 | B24: Mary Davis | C24: West | D24: Books | E24: 743.17 | F24: 9 | G24: 0 | H24: 45416 | I24: 297.27 | J24: =SUMIFS($E$2:$E$201,$A$2:$A$201,A24) -> 4640.11 | K24: =IF(INDEX('Pivot Table'!$N$5:$N$34,MATCH(A24,'Pivot Table'!$I$5:$I$34,0))<=10,"Top 10","") | L24: =ROUND(E24/(1-G24),2) -> 743.17 | M24: =ROUND(L24*(1-$U$3),2) -> 668.85 | N24: =ROUND(M24-(E24-I24),2) -> 222.95 | O24: =I24/E24 -> 0.40000269 | P24: =DATE(YEAR(H24),MONTH(H24),1) -> 45413 | Q24: =IF(J24>='Pivot Table'!$R$4,"High Value","Standard") -> Standard | R24: =NOW() -> 46304.64
A25: CUST023 | B25: Mary Davis | C25: Central | D25: Electronics | E25: 706.37 | F25: 6 | G25: 0 | H25: 45416 | I25: 176.59 | J25: =SUMIFS($E$2:$E$201,$A$2:$A$201,A25) -> 5913.68 | K25: =IF(INDEX('Pivot Table'!$N$5:$N$34,MATCH(A25,'Pivot Table'!$I$5:$I$34,0))<=10,"Top 10","") | L25: =ROUND(E25/(1-G25),2) -> 706.37 | M25: =ROUND(L25*(1-$U$3),2) -> 635.73 | N25: =ROUND(M25-(E25-I25),2) -> 105.95 | O25: =I25/E25 -> 0.24999646 | P25: =DATE(YEAR(H25),MONTH(H25),1) -> 45413 | Q25: =IF(J25>='Pivot Table'!$R$4,"High Value","Standard") -> Standard | R25: =NOW() -> 46304.64
A26: CUST012 | B26: Mary Davis | C26: Central | D26: Office Supplies | E26: 925.31 | F26: 8 | G26: 0.1 | H26: 45418 | I26: 374.75 | J26: =SUMIFS($E$2:$E$201,$A$2:$A$201,A26) -> 8339 | K26: =IF(INDEX('Pivot Table'!$N$5:$N$34,MATCH(A26,'Pivot Table'!$I$5:$I$34,0))<=10,"Top 10","") -> Top 10 | L26: =ROUND(E26/(1-G26),2) -> 1028.12 | M26: =ROUND(L26*(1-$U$3),2) -> 925.31 | N26: =ROUND(M26-(E26-I26),2) -> 374.75 | O26: =I26/E26 -> 0.40499941 | P26: =DATE(YEAR(H26),MONTH(H26),1) -> 45413 | Q26: =IF(J26>='Pivot Table'!$R$4,"High Value","Standard") -> High Value | R26: =NOW() -> 46304.64
A27: CUST010 | B27: Linda Brown | C27: South | D27: Electronics | E27: 1173.12 | F27: 18 | G27: 0 | H27: 45418 | I27: 293.28 | J27: =SUMIFS($E$2:$E$201,$A$2:$A$201,A27) -> 4259.22 | K27: =IF(INDEX('Pivot Table'!$N$5:$N$34,MATCH(A27,'Pivot Table'!$I$5:$I$34,0))<=10,"Top 10","") | L27: =ROUND(E27/(1-G27),2) -> 1173.12 | M27: =ROUND(L27*(1-$U$3),2) -> 1055.81 | N27: =ROUND(M27-(E27-I27),2) -> 175.97 | O27: =I27/E27 -> 0.25 | P27: =DATE(YEAR(H27),MONTH(H27),1) -> 45413 | Q27: =IF(J27>='Pivot Table'!$R$4,"High Value","Standard") -> Standard | R27: =NOW() -> 46304.64
A28: CUST030 | B28: John Brown | C28: North | D28: Furniture | E28: 675.54 | F28: 17 | G28: 0 | H28: 45420 | I28: 236.44 | J28: =SUMIFS($E$2:$E$201,$A$2:$A$201,A28) -> 7928.71 | K28: =IF(INDEX('Pivot Table'!$N$5:$N$34,MATCH(A28,'Pivot Table'!$I$5:$I$34,0))<=10,"Top 10","") -> Top 10 | L28: =ROUND(E28/(1-G28),2) -> 675.54 | M28: =ROUND(L28*(1-$U$3),2) -> 607.99 | N28: =ROUND(M28-(E28-I28),2) -> 168.89 | O28: =I28/E28 -> 0.35000148 | P28: =DATE(YEAR(H28),MONTH(H28),1) -> 45413 | Q28: =IF(J28>='Pivot Table'!$R$4,"High Value","Standard") -> Standard | R28: =NOW() -> 46304.64
A29: CUST007 | B29: Robert Anderson | C29: Central | D29: Books | E29: 939.09 | F29: 2 | G29: 0.05 | H29: 45422 | I29: 356.85 | J29: =SUMIFS($E$2:$E$201,$A$2:$A$201,A29) -> 9941.88 | K29: =IF(INDEX('Pivot Table'!$N$5:$N$34,MATCH(A29,'Pivot Table'!$I$5:$I$34,0))<=10,"Top 10","") -> Top 10 | L29: =ROUND(E29/(1-G29),2) -> 988.52 | M29: =ROUND(L29*(1-$U$3),2) -> 889.67 | N29: =ROUND(M29-(E29-I29),2) -> 307.43 | O29: =I29/E29 -> 0.37999553 | P29: =DATE(YEAR(H29),MONTH(H29),1) -> 45413 | Q29: =IF(J29>='Pivot Table'!$R$4,"High Value","Standard") -> High Value | R29: =NOW() -> 46304.64
A30: CUST028 | B30: Linda Taylor | C30: East | D30: Office Supplies | E30: 983.34 | F30: 19 | G30: 0.1 | H30: 45426 | I30: 398.25 | J30: =SUMIFS($E$2:$E$201,$A$2:$A$201,A30) -> 10293.87 | K30: =IF(INDEX('Pivot Table'!$N$5:$N$34,MATCH(A30,'Pivot Table'!$I$5:$I$34,0))<=10,"Top 10","") -> Top 10 | L30: =ROUND(E30/(1-G30),2) -> 1092.6 | M30: =ROUND(L30*(1-$U$3),2) -> 983.34 | N30: =ROUND(M30-(E30-I30),2) -> 398.25 | O30: =I30/E30 -> 0.40499725 | P30: =DATE(YEAR(H30),MONTH(H30),1) -> 45413 | Q30: =IF(J30>='Pivot Table'!$R$4,"High Value","Standard") -> High Value | R30: =NOW() -> 46304.64
A31: CUST028 | B31: James Wilson | C31: South | D31: Electronics | E31: 801.21 | F31: 3 | G31: 0.2 | H31: 45426 | I31: 160.24 | J31: =SUMIFS($E$2:$E$201,$A$2:$A$201,A31) -> 10293.87 | K31: =IF(INDEX('Pivot Table'!$N$5:$N$34,MATCH(A31,'Pivot Table'!$I$5:$I$34,0))<=10,"Top 10","") -> Top 10 | L31: =ROUND(E31/(1-G31),2) -> 1001.51 | M31: =ROUND(L31*(1-$U$3),2) -> 901.36 | N31: =ROUND(M31-(E31-I31),2) -> 260.39 | O31: =I31/E31 -> 0.1999975 | P31: =DATE(YEAR(H31),MONTH(H31),1) -> 45413 | Q31: =IF(J31>='Pivot Table'!$R$4,"High Value","Standard") -> High Value | R31: =NOW() -> 46304.64
A32: CUST025 | B32: David Brown | C32: North | D32: Electronics | E32: 1450.71 | F32: 5 | G32: 0.1 | H32: 45427 | I32: 326.41 | J32: =SUMIFS($E$2:$E$201,$A$2:$A$201,A32) -> 6716.52 | K32: =IF(INDEX('Pivot Table'!$N$5:$N$34,MATCH(A32,'Pivot Table'!$I$5:$I$34,0))<=10,"Top 10","") | L32: =ROUND(E32/(1-G32),2) -> 1611.9 | M32: =ROUND(L32*(1-$U$3),2) -> 1450.71 | N32: =ROUND(M32-(E32-I32),2) -> 326.41 | O32: =I32/E32 -> 0.22500017 | P32: =DATE(YEAR(H32),MONTH(H32),1) -> 45413 | Q32: =IF(J32>='Pivot Table'!$R$4,"High Value","Standard") -> Standard | R32: =NOW() -> 46304.64
A33: CUST022 | B33: David Davis | C33: Central | D33: Books | E33: 1023.21 | F33: 18 | G33: 0.05 | H33: 45428 | I33: 388.82 | J33: =SUMIFS($E$2:$E$201,$A$2:$A$201,A33) -> 4418.28 | K33: =IF(INDEX('Pivot Table'!$N$5:$N$34,MATCH(A33,'Pivot Table'!$I$5:$I$34,0))<=10,"Top 10","") | L33: =ROUND(E33/(1-G33),2) -> 1077.06 | M33: =ROUND(L33*(1-$U$3),2) -> 969.35 | N33: =ROUND(M33-(E33-I33),2) -> 334.96 | O33: =I33/E33 -> 0.3800002 | P33: =DATE(YEAR(H33),MONTH(H33),1) -> 45413 | Q33: =IF(J33>='Pivot Table'!$R$4,"High Value","Standard") -> Standard | R33: =NOW() -> 46304.64
A34: CUST001 | B34: Mary Jackson | C34: West | D34: Furniture | E34: 853.72 | F34: 5 | G34: 0.15 | H34: 45428 | I34: 253.98 | J34: =SUMIFS($E$2:$E$201,$A$2:$A$201,A34) -> 6549.55 | K34: =IF(INDEX('Pivot Table'!$N$5:$N$34,MATCH(A34,'Pivot Table'!$I$5:$I$34,0))<=10,"Top 10","") | L34: =ROUND(E34/(1-G34),2) -> 1004.38 | M34: =ROUND(L34*(1-$U$3),2) -> 903.94 | N34: =ROUND(M34-(E34-I34),2) -> 304.2 | O34: =I34/E34 -> 0.29749801 | P34: =DATE(YEAR(H34),MONTH(H34),1) -> 45413 | Q34: =IF(J34>='Pivot Table'!$R$4,"High Value","Standard") -> Standard | R34: =NOW() -> 46304.64
... A41: CUST016 | B41: Emma Wilson | C41: East | D41: Books | E41: 580.43 | F41: 19 | G41: 0.15 | H41: 45435 | I41: 197.35 | J41: =SUMIFS($E$2:$E$201,$A$2:$A$201,A41) -> 3369.17 | K41: =IF(INDEX('Pivot Table'!$N$5:$N$34,MATCH(A41,'Pivot Table'!$I$5:$I$34,0))<=10,"Top 10","") | L41: =ROUND(E41/(1-G41),2) -> 682.86 | M41: =ROUND(L41*(1-$U$3),2) -> 614.57 | N41: =ROUND(M41-(E41-I41),2) -> 231.49 | O41: =I41/E41 -> 0.34000655 | P41: =DATE(YEAR(H41),MONTH(H41),1) -> 45413 | Q41: =IF(J41>='Pivot Table'!$R$4,"High Value","Standard") -> Standard | R41: =NOW() -> 46304.64
A42: CUST005 | B42: David Smith | C42: South | D42: Books | E42: 1151.21 | F42: 15 | G42: 0.1 | H42: 45445 | I42: 414.44 | J42: =SUMIFS($E$2:$E$201,$A$2:$A$201,A42) -> 6666.13 | K42: =IF(INDEX('Pivot Table'!$N$5:$N$34,MATCH(A42,'Pivot Table'!$I$5:$I$34,0))<=10,"Top 10","") | L42: =ROUND(E42/(1-G42),2) -> 1279.12 | M42: =ROUND(L42*(1-$U$3),2) -> 1151.21 | N42: =ROUND(M42-(E42-I42),2) -> 414.44 | O42: =I42/E42 -> 0.36000382 | P42: =DATE(YEAR(H42),MONTH(H42),1) -> 45444 | Q42: =IF(J42>='Pivot Table'!$R$4,"High Value","Standard") -> Standard | R42: =NOW() -> 46304.64 | T42: DESCRIPTIVE STATISTICS – ToolPak-format table for Sales, Quantity, Discount, Profit (values computed to match Excel)
A43: CUST028 | B43: James Wilson | C43: Central | D43: Office Supplies | E43: 1025.98 | F43: 5 | G43: 0.2 | H43: 45447 | I43: 369.35 | J43: =SUMIFS($E$2:$E$201,$A$2:$A$201,A43) -> 10293.87 | K43: =IF(INDEX('Pivot Table'!$N$5:$N$34,MATCH(A43,'Pivot Table'!$I$5:$I$34,0))<=10,"Top 10","") -> Top 10 | L43: =ROUND(E43/(1-G43),2) -> 1282.48 | M43: =ROUND(L43*(1-$U$3),2) -> 1154.23 | N43: =ROUND(M43-(E43-I43),2) -> 497.6 | O43: =I43/E43 -> 0.35999727 | P43: =DATE(YEAR(H43),MONTH(H43),1) -> 45444 | Q43: =IF(J43>='Pivot Table'!$R$4,"High Value","Standard") -> High Value | R43: =NOW() -> 46304.64 | T43: Sales | V43: Quantity | X43: Discount | Z43: Profit
A44: CUST023 | B44: David Davis | C44: East | D44: Office Supplies | E44: 556.42 | F44: 11 | G44: 0.15 | H44: 45447 | I44: 212.83 | J44: =SUMIFS($E$2:$E$201,$A$2:$A$201,A44) -> 5913.68 | K44: =IF(INDEX('Pivot Table'!$N$5:$N$34,MATCH(A44,'Pivot Table'!$I$5:$I$34,0))<=10,"Top 10","") | L44: =ROUND(E44/(1-G44),2) -> 654.61 | M44: =ROUND(L44*(1-$U$3),2) -> 589.15 | N44: =ROUND(M44-(E44-I44),2) -> 245.56 | O44: =I44/E44 -> 0.38249883 | P44: =DATE(YEAR(H44),MONTH(H44),1) -> 45444 | Q44: =IF(J44>='Pivot Table'!$R$4,"High Value","Standard") -> Standard | R44: =NOW() -> 46304.64 | T44: Mean | U44: 976.0888 | V44: Mean | W44: 9.995 | X44: Mean | Y44: 0.09725 | Z44: Mean | AA44: 341.43505
A45: CUST021 | B45: James Wilson | C45: Central | D45: Books | E45: 840.85 | F45: 19 | G45: 0.1 | H45: 45448 | I45: 302.71 | J45: =SUMIFS($E$2:$E$201,$A$2:$A$201,A45) -> 8740.18 | K45: =IF(INDEX('Pivot Table'!$N$5:$N$34,MATCH(A45,'Pivot Table'!$I$5:$I$34,0))<=10,"Top 10","") -> Top 10 | L45: =ROUND(E45/(1-G45),2) -> 934.28 | M45: =ROUND(L45*(1-$U$3),2) -> 840.85 | N45: =ROUND(M45-(E45-I45),2) -> 302.71 | O45: =I45/E45 -> 0.36000476 | P45: =DATE(YEAR(H45),MONTH(H45),1) -> 45444 | Q45: =IF(J45>='Pivot Table'!$R$4,"High Value","Standard") -> High Value | R45: =NOW() -> 46304.64 | T45: Standard Error | U45: 21.16185 | V45: Standard Error | W45: 0.39927683 | X45: Standard Error | Y45: 0.0051142414 | Z45: Standard Error | AA45: 9.6001196
A46: CUST026 | B46: Emma Wilson | C46: North | D46: Furniture | E46: 1227.25 | F46: 12 | G46: 0.15 | H46: 45448 | I46: 365.11 | J46: =SUMIFS($E$2:$E$201,$A$2:$A$201,A46) -> 9371.81 | K46: =IF(INDEX('Pivot Table'!$N$5:$N$34,MATCH(A46,'Pivot Table'!$I$5:$I$34,0))<=10,"Top 10","") -> Top 10 | L46: =ROUND(E46/(1-G46),2) -> 1443.82 | M46: =ROUND(L46*(1-$U$3),2) -> 1299.44 | N46: =ROUND(M46-(E46-I46),2) -> 437.3 | O46: =I46/E46 -> 0.29750255 | P46: =DATE(YEAR(H46),MONTH(H46),1) -> 45444 | Q46: =IF(J46>='Pivot Table'!$R$4,"High Value","Standard") -> High Value | R46: =NOW() -> 46304.64 | T46: Median | U46: 976.72 | V46: Median | W46: 10 | X46: Median | Y46: 0.1 | Z46: Median | AA46: 332.255
...

Sheet Pivot Table
A1: PIVOT TABLES – SALES ANALYSIS
A3: 1. TOTAL SALES BY REGION × PRODUCT CATEGORY | I3: 5. CUSTOMER ANALYSIS (SUMIFS group-by + INDEX/MATCH) | Q3: 6. HIGH-VALUE CUSTOMERS (INDEX / MATCH)
A4: Region | B4: Books | C4: Clothing | D4: Electronics | E4: Furniture | F4: Office Supplies | G4: Grand Total | I4: Customer ID | J4: Name (first recorded) | K4: Orders | L4: Total Sales | M4: Total Profit | N4: Rank | O4: Tier | Q4: High-value threshold (75th percentile of Total Sales) | R4: =ROUND(PERCENTILE($L$5:$L$34,0.75),2) -> 8236.43
A5: Central | B5: =SUMIFS(Dataset!$E$2:$E$201,Dataset!$C$2:$C$201,$A5,Dataset!$D$2:$D$201,B$4) -> 11297.15 | C5: =SUMIFS(Dataset!$E$2:$E$201,Dataset!$C$2:$C$201,$A5,Dataset!$D$2:$D$201,C$4) -> 12200.26 | D5: =SUMIFS(Dataset!$E$2:$E$201,Dataset!$C$2:$C$201,$A5,Dataset!$D$2:$D$201,D$4) -> 6621.24 | E5: =SUMIFS(Dataset!$E$2:$E$201,Dataset!$C$2:$C$201,$A5,Dataset!$D$2:$D$201,E$4) -> 4876.96 | F5: =SUMIFS(Dataset!$E$2:$E$201,Dataset!$C$2:$C$201,$A5,Dataset!$D$2:$D$201,F$4) -> 8472.72 | G5: =SUM(B5:F5) -> 43468.33 | I5: CUST001 | J5: =INDEX(Dataset!$B$2:$B$201,MATCH(I5,Dataset!$A$2:$A$201,0)) -> Linda Wilson | K5: =COUNTIFS(Dataset!$A$2:$A$201,I5) -> 7 | L5: =SUMIFS(Dataset!$E$2:$E$201,Dataset!$A$2:$A$201,I5) -> 6549.55 | M5: =SUMIFS(Dataset!$I$2:$I$201,Dataset!$A$2:$A$201,I5) -> 1868.77 | N5: =RANK(L5,$L$5:$L$34)+COUNTIF($L$5:L5,L5)-1 -> 15 | O5: =IF(L5>=$R$4,"High Value","Standard") -> Standard | Q5: Number of high-value customers | R5: =COUNTIF($O$5:$O$34,"High Value") -> 8
A6: East | B6: =SUMIFS(Dataset!$E$2:$E$201,Dataset!$C$2:$C$201,$A6,Dataset!$D$2:$D$201,B$4) -> 11389.09 | C6: =SUMIFS(Dataset!$E$2:$E$201,Dataset!$C$2:$C$201,$A6,Dataset!$D$2:$D$201,C$4) -> 2401.45 | D6: =SUMIFS(Dataset!$E$2:$E$201,Dataset!$C$2:$C$201,$A6,Dataset!$D$2:$D$201,D$4) -> 2869.54 | E6: =SUMIFS(Dataset!$E$2:$E$201,Dataset!$C$2:$C$201,$A6,Dataset!$D$2:$D$201,E$4) -> 7592.34 | F6: =SUMIFS(Dataset!$E$2:$E$201,Dataset!$C$2:$C$201,$A6,Dataset!$D$2:$D$201,F$4) -> 8189.22 | G6: =SUM(B6:F6) -> 32441.64 | I6: CUST002 | J6: =INDEX(Dataset!$B$2:$B$201,MATCH(I6,Dataset!$A$2:$A$201,0)) -> Lisa Davis | K6: =COUNTIFS(Dataset!$A$2:$A$201,I6) -> 6 | L6: =SUMIFS(Dataset!$E$2:$E$201,Dataset!$A$2:$A$201,I6) -> 6481.43 | M6: =SUMIFS(Dataset!$I$2:$I$201,Dataset!$A$2:$A$201,I6) -> 2210.74 | N6: =RANK(L6,$L$5:$L$34)+COUNTIF($L$5:L6,L6)-1 -> 17 | O6: =IF(L6>=$R$4,"High Value","Standard") -> Standard | Q6: Rank | R6: Customer ID | S6: Name (first recorded) | T6: Total Sales | U6: Total Profit
A7: North | B7: =SUMIFS(Dataset!$E$2:$E$201,Dataset!$C$2:$C$201,$A7,Dataset!$D$2:$D$201,B$4) -> 8037.01 | C7: =SUMIFS(Dataset!$E$2:$E$201,Dataset!$C$2:$C$201,$A7,Dataset!$D$2:$D$201,C$4) -> 8422.82 | D7: =SUMIFS(Dataset!$E$2:$E$201,Dataset!$C$2:$C$201,$A7,Dataset!$D$2:$D$201,D$4) -> 8191.71 | E7: =SUMIFS(Dataset!$E$2:$E$201,Dataset!$C$2:$C$201,$A7,Dataset!$D$2:$D$201,E$4) -> 6978.08 | F7: =SUMIFS(Dataset!$E$2:$E$201,Dataset!$C$2:$C$201,$A7,Dataset!$D$2:$D$201,F$4) -> 3345.8 | G7: =SUM(B7:F7) -> 34975.42 | I7: CUST003 | J7: =INDEX(Dataset!$B$2:$B$201,MATCH(I7,Dataset!$A$2:$A$201,0)) -> Emma Davis | K7: =COUNTIFS(Dataset!$A$2:$A$201,I7) -> 9 | L7: =SUMIFS(Dataset!$E$2:$E$201,Dataset!$A$2:$A$201,I7) -> 8490.18 | M7: =SUMIFS(Dataset!$I$2:$I$201,Dataset!$A$2:$A$201,I7) -> 2652.75 | N7: =RANK(L7,$L$5:$L$34)+COUNTIF($L$5:L7,L7)-1 -> 7 | O7: =IF(L7>=$R$4,"High Value","Standard") -> High Value | Q7: =IF(ROWS(Q$7:Q7)<=$R$5,ROWS(Q$7:Q7),"") -> 1 | R7: =IF($Q7="","",INDEX($I$5:$I$34,MATCH($Q7,$N$5:$N$34,0))) -> CUST015 | S7: =IF($Q7="","",INDEX($J$5:$J$34,MATCH($Q7,$N$5:$N$34,0))) -> Linda Taylor | T7: =IF($Q7="","",INDEX($L$5:$L$34,MATCH($Q7,$N$5:$N$34,0))) -> 11611.06 | U7: =IF($Q7="","",INDEX($M$5:$M$34,MATCH($Q7,$N$5:$N$34,0))) -> 4201.59
A8: South | B8: =SUMIFS(Dataset!$E$2:$E$201,Dataset!$C$2:$C$201,$A8,Dataset!$D$2:$D$201,B$4) -> 9588.04 | C8: =SUMIFS(Dataset!$E$2:$E$201,Dataset!$C$2:$C$201,$A8,Dataset!$D$2:$D$201,C$4) -> 8393.63 | D8: =SUMIFS(Dataset!$E$2:$E$201,Dataset!$C$2:$C$201,$A8,Dataset!$D$2:$D$201,D$4) -> 11989.07 | E8: =SUMIFS(Dataset!$E$2:$E$201,Dataset!$C$2:$C$201,$A8,Dataset!$D$2:$D$201,E$4) -> 7982.73 | F8: =SUMIFS(Dataset!$E$2:$E$201,Dataset!$C$2:$C$201,$A8,Dataset!$D$2:$D$201,F$4) -> 2295.32 | G8: =SUM(B8:F8) -> 40248.79 | I8: CUST004 | J8: =INDEX(Dataset!$B$2:$B$201,MATCH(I8,Dataset!$A$2:$A$201,0)) -> Lisa Thomas | K8: =COUNTIFS(Dataset!$A$2:$A$201,I8) -> 7 | L8: =SUMIFS(Dataset!$E$2:$E$201,Dataset!$A$2:$A$201,I8) -> 7813.59 | M8: =SUMIFS(Dataset!$I$2:$I$201,Dataset!$A$2:$A$201,I8) -> 3211.82 | N8: =RANK(L8,$L$5:$L$34)+COUNTIF($L$5:L8,L8)-1 -> 10 | O8: =IF(L8>=$R$4,"High Value","Standard") -> Standard | Q8: =IF(ROWS(Q$7:Q8)<=$R$5,ROWS(Q$7:Q8),"") -> 2 | R8: =IF($Q8="","",INDEX($I$5:$I$34,MATCH($Q8,$N$5:$N$34,0))) -> CUST028 | S8: =IF($Q8="","",INDEX($J$5:$J$34,MATCH($Q8,$N$5:$N$34,0))) -> Linda Taylor | T8: =IF($Q8="","",INDEX($L$5:$L$34,MATCH($Q8,$N$5:$N$34,0))) -> 10293.87 | U8: =IF($Q8="","",INDEX($M$5:$M$34,MATCH($Q8,$N$5:$N$34,0))) -> 3541.02
A9: West | B9: =SUMIFS(Dataset!$E$2:$E$201,Dataset!$C$2:$C$201,$A9,Dataset!$D$2:$D$201,B$4) -> 6691.17 | C9: =SUMIFS(Dataset!$E$2:$E$201,Dataset!$C$2:$C$201,$A9,Dataset!$D$2:$D$201,C$4) -> 10509.43 | D9: =SUMIFS(Dataset!$E$2:$E$201,Dataset!$C$2:$C$201,$A9,Dataset!$D$2:$D$201,D$4) -> 11372.44 | E9: =SUMIFS(Dataset!$E$2:$E$201,Dataset!$C$2:$C$201,$A9,Dataset!$D$2:$D$201,E$4) -> 9182.78 | F9: =SUMIFS(Dataset!$E$2:$E$201,Dataset!$C$2:$C$201,$A9,Dataset!$D$2:$D$201,F$4) -> 6327.76 | G9: =SUM(B9:F9) -> 44083.58 | I9: CUST005 | J9: =INDEX(Dataset!$B$2:$B$201,MATCH(I9,Dataset!$A$2:$A$201,0)) -> Robert Anderson | K9: =COUNTIFS(Dataset!$A$2:$A$201,I9) -> 6 | L9: =SUMIFS(Dataset!$E$2:$E$201,Dataset!$A$2:$A$201,I9) -> 6666.13 | M9: =SUMIFS(Dataset!$I$2:$I$201,Dataset!$A$2:$A$201,I9) -> 1982.39 | N9: =RANK(L9,$L$5:$L$34)+COUNTIF($L$5:L9,L9)-1 -> 14 | O9: =IF(L9>=$R$4,"High Value","Standard") -> Standard | Q9: =IF(ROWS(Q$7:Q9)<=$R$5,ROWS(Q$7:Q9),"") -> 3 | R9: =IF($Q9="","",INDEX($I$5:$I$34,MATCH($Q9,$N$5:$N$34,0))) -> CUST007 | S9: =IF($Q9="","",INDEX($J$5:$J$34,MATCH($Q9,$N$5:$N$34,0))) -> Michael Anderson | T9: =IF($Q9="","",INDEX($L$5:$L$34,MATCH($Q9,$N$5:$N$34,0))) -> 9941.88 | U9: =IF($Q9="","",INDEX($M$5:$M$34,MATCH($Q9,$N$5:$N$34,0))) -> 3936.26
A10: Grand Total | B10: =SUM(B5:B9) -> 47002.46 | C10: =SUM(C5:C9) -> 41927.59 | D10: =SUM(D5:D9) -> 41044 | E10: =SUM(E5:E9) -> 36612.89 | F10: =SUM(F5:F9) -> 28630.82 | G10: =SUM(G5:G9) -> 195217.76 | I10: CUST006 | J10: =INDEX(Dataset!$B$2:$B$201,MATCH(I10,Dataset!$A$2:$A$201,0)) -> Mary Jackson | K10: =COUNTIFS(Dataset!$A$2:$A$201,I10) -> 2 | L10: =SUMIFS(Dataset!$E$2:$E$201,Dataset!$A$2:$A$201,I10) -> 2699.75 | M10: =SUMIFS(Dataset!$I$2:$I$201,Dataset!$A$2:$A$201,I10) -> 837.06 | N10: =RANK(L10,$L$5:$L$34)+COUNTIF($L$5:L10,L10)-1 -> 30 | O10: =IF(L10>=$R$4,"High Value","Standard") -> Standard | Q10: =IF(ROWS(Q$7:Q10)<=$R$5,ROWS(Q$7:Q10),"") -> 4 | R10: =IF($Q10="","",INDEX($I$5:$I$34,MATCH($Q10,$N$5:$N$34,0))) -> CUST008 | S10: =IF($Q10="","",INDEX($J$5:$J$34,MATCH($Q10,$N$5:$N$34,0))) -> Robert Anderson | T10: =IF($Q10="","",INDEX($L$5:$L$34,MATCH($Q10,$N$5:$N$34,0))) -> 9760.8 | U10: =IF($Q10="","",INDEX($M$5:$M$34,MATCH($Q10,$N$5:$N$34,0))) -> 3442.48
I11: CUST007 | J11: =INDEX(Dataset!$B$2:$B$201,MATCH(I11,Dataset!$A$2:$A$201,0)) -> Michael Anderson | K11: =COUNTIFS(Dataset!$A$2:$A$201,I11) -> 10 | L11: =SUMIFS(Dataset!$E$2:$E$201,Dataset!$A$2:$A$201,I11) -> 9941.88 | M11: =SUMIFS(Dataset!$I$2:$I$201,Dataset!$A$2:$A$201,I11) -> 3936.26 | N11: =RANK(L11,$L$5:$L$34)+COUNTIF($L$5:L11,L11)-1 -> 3 | O11: =IF(L11>=$R$4,"High Value","Standard") -> High Value | Q11: =IF(ROWS(Q$7:Q11)<=$R$5,ROWS(Q$7:Q11),"") -> 5 | R11: =IF($Q11="","",INDEX($I$5:$I$34,MATCH($Q11,$N$5:$N$34,0))) -> CUST026 | S11: =IF($Q11="","",INDEX($J$5:$J$34,MATCH($Q11,$N$5:$N$34,0))) -> Mary Davis | T11: =IF($Q11="","",INDEX($L$5:$L$34,MATCH($Q11,$N$5:$N$34,0))) -> 9371.81 | U11: =IF($Q11="","",INDEX($M$5:$M$34,MATCH($Q11,$N$5:$N$34,0))) -> 2922.02
I12: CUST008 | J12: =INDEX(Dataset!$B$2:$B$201,MATCH(I12,Dataset!$A$2:$A$201,0)) -> Robert Anderson | K12: =COUNTIFS(Dataset!$A$2:$A$201,I12) -> 10 | L12: =SUMIFS(Dataset!$E$2:$E$201,Dataset!$A$2:$A$201,I12) -> 9760.8 | M12: =SUMIFS(Dataset!$I$2:$I$201,Dataset!$A$2:$A$201,I12) -> 3442.48 | N12: =RANK(L12,$L$5:$L$34)+COUNTIF($L$5:L12,L12)-1 -> 4 | O12: =IF(L12>=$R$4,"High Value","Standard") -> High Value | Q12: =IF(ROWS(Q$7:Q12)<=$R$5,ROWS(Q$7:Q12),"") -> 6 | R12: =IF($Q12="","",INDEX($I$5:$I$34,MATCH($Q12,$N$5:$N$34,0))) -> CUST021 | S12: =IF($Q12="","",INDEX($J$5:$J$34,MATCH($Q12,$N$5:$N$34,0))) -> Sarah Anderson | T12: =IF($Q12="","",INDEX($L$5:$L$34,MATCH($Q12,$N$5:$N$34,0))) -> 8740.18 | U12: =IF($Q12="","",INDEX($M$5:$M$34,MATCH($Q12,$N$5:$N$34,0))) -> 2848.62
A13: 2. REGION SUMMARY | I13: CUST009 | J13: =INDEX(Dataset!$B$2:$B$201,MATCH(I13,Dataset!$A$2:$A$201,0)) -> Linda Jackson | K13: =COUNTIFS(Dataset!$A$2:$A$201,I13) -> 7 | L13: =SUMIFS(Dataset!$E$2:$E$201,Dataset!$A$2:$A$201,I13) -> 6505.2 | M13: =SUMIFS(Dataset!$I$2:$I$201,Dataset!$A$2:$A$201,I13) -> 2052.54 | N13: =RANK(L13,$L$5:$L$34)+COUNTIF($L$5:L13,L13)-1 -> 16 | O13: =IF(L13>=$R$4,"High Value","Standard") -> Standard | Q13: =IF(ROWS(Q$7:Q13)<=$R$5,ROWS(Q$7:Q13),"") -> 7 | R13: =IF($Q13="","",INDEX($I$5:$I$34,MATCH($Q13,$N$5:$N$34,0))) -> CUST003 | S13: =IF($Q13="","",INDEX($J$5:$J$34,MATCH($Q13,$N$5:$N$34,0))) -> Emma Davis | T13: =IF($Q13="","",INDEX($L$5:$L$34,MATCH($Q13,$N$5:$N$34,0))) -> 8490.18 | U13: =IF($Q13="","",INDEX($M$5:$M$34,MATCH($Q13,$N$5:$N$34,0))) -> 2652.75
A14: Region | B14: Orders | C14: Sales | D14: Profit | E14: Profit Margin | F14: Avg Discount | I14: CUST010 | J14: =INDEX(Dataset!$B$2:$B$201,MATCH(I14,Dataset!$A$2:$A$201,0)) -> David Thomas | K14: =COUNTIFS(Dataset!$A$2:$A$201,I14) -> 5 | L14: =SUMIFS(Dataset!$E$2:$E$201,Dataset!$A$2:$A$201,I14) -> 4259.22 | M14: =SUMIFS(Dataset!$I$2:$I$201,Dataset!$A$2:$A$201,I14) -> 1529.32 | N14: =RANK(L14,$L$5:$L$34)+COUNTIF($L$5:L14,L14)-1 -> 24 | O14: =IF(L14>=$R$4,"High Value","Standard") -> Standard | Q14: =IF(ROWS(Q$7:Q14)<=$R$5,ROWS(Q$7:Q14),"") -> 8 | R14: =IF($Q14="","",INDEX($I$5:$I$34,MATCH($Q14,$N$5:$N$34,0))) -> CUST012 | S14: =IF($Q14="","",INDEX($J$5:$J$34,MATCH($Q14,$N$5:$N$34,0))) -> Robert Anderson | T14: =IF($Q14="","",INDEX($L$5:$L$34,MATCH($Q14,$N$5:$N$34,0))) -> 8339 | U14: =IF($Q14="","",INDEX($M$5:$M$34,MATCH($Q14,$N$5:$N$34,0))) -> 2988.71
A15: Central | B15: =COUNTIFS(Dataset!$C$2:$C$201,$A15) -> 44 | C15: =SUMIFS(Dataset!$E$2:$E$201,Dataset!$C$2:$C$201,$A15) -> 43468.33 | D15: =SUMIFS(Dataset!$I$2:$I$201,Dataset!$C$2:$C$201,$A15) -> 16068.4 | E15: =D15/C15 -> 0.36965763 | F15: =AVERAGEIFS(Dataset!$G$2:$G$201,Dataset!$C$2:$C$201,$A15) -> 0.086363636 | I15: CUST011 | J15: =INDEX(Dataset!$B$2:$B$201,MATCH(I15,Dataset!$A$2:$A$201,0)) -> Mary Davis | K15: =COUNTIFS(Dataset!$A$2:$A$201,I15) -> 4 | L15: =SUMIFS(Dataset!$E$2:$E$201,Dataset!$A$2:$A$201,I15) -> 3762.29 | M15: =SUMIFS(Dataset!$I$2:$I$201,Dataset!$A$2:$A$201,I15) -> 1545.04 | N15: =RANK(L15,$L$5:$L$34)+COUNTIF($L$5:L15,L15)-1 -> 27 | O15: =IF(L15>=$R$4,"High Value","Standard") -> Standard | Q15: =IF(ROWS(Q$7:Q15)<=$R$5,ROWS(Q$7:Q15),"") | R15: =IF($Q15="","",INDEX($I$5:$I$34,MATCH($Q15,$N$5:$N$34,0))) | S15: =IF($Q15="","",INDEX($J$5:$J$34,MATCH($Q15,$N$5:$N$34,0))) | T15: =IF($Q15="","",INDEX($L$5:$L$34,MATCH($Q15,$N$5:$N$34,0))) | U15: =IF($Q15="","",INDEX($M$5:$M$34,MATCH($Q15,$N$5:$N$34,0)))
A16: East | B16: =COUNTIFS(Dataset!$C$2:$C$201,$A16) -> 32 | C16: =SUMIFS(Dataset!$E$2:$E$201,Dataset!$C$2:$C$201,$A16) -> 32441.64 | D16: =SUMIFS(Dataset!$I$2:$I$201,Dataset!$C$2:$C$201,$A16) -> 11638.59 | E16: =D16/C16 -> 0.35875467 | F16: =AVERAGEIFS(Dataset!$G$2:$G$201,Dataset!$C$2:$C$201,$A16) -> 0.0921875 | I16: CUST012 | J16: =INDEX(Dataset!$B$2:$B$201,MATCH(I16,Dataset!$A$2:$A$201,0)) -> Robert Anderson | K16: =COUNTIFS(Dataset!$A$2:$A$201,I16) -> 9 | L16: =SUMIFS(Dataset!$E$2:$E$201,Dataset!$A$2:$A$201,I16) -> 8339 | M16: =SUMIFS(Dataset!$I$2:$I$201,Dataset!$A$2:$A$201,I16) -> 2988.71 | N16: =RANK(L16,$L$5:$L$34)+COUNTIF($L$5:L16,L16)-1 -> 8 | O16: =IF(L16>=$R$4,"High Value","Standard") -> High Value | Q16: =IF(ROWS(Q$7:Q16)<=$R$5,ROWS(Q$7:Q16),"") | R16: =IF($Q16="","",INDEX($I$5:$I$34,MATCH($Q16,$N$5:$N$34,0))) | S16: =IF($Q16="","",INDEX($J$5:$J$34,MATCH($Q16,$N$5:$N$34,0))) | T16: =IF($Q16="","",INDEX($L$5:$L$34,MATCH($Q16,$N$5:$N$34,0))) | U16: =IF($Q16="","",INDEX($M$5:$M$34,MATCH($Q16,$N$5:$N$34,0)))
A17: North | B17: =COUNTIFS(Dataset!$C$2:$C$201,$A17) -> 39 | C17: =SUMIFS(Dataset!$E$2:$E$201,Dataset!$C$2:$C$201,$A17) -> 34975.42 | D17: =SUMIFS(Dataset!$I$2:$I$201,Dataset!$C$2:$C$201,$A17) -> 11902.28 | E17: =D17/C17 -> 0.34030413 | F17: =AVERAGEIFS(Dataset!$G$2:$G$201,Dataset!$C$2:$C$201,$A17) -> 0.11666667 | I17: CUST013 | J17: =INDEX(Dataset!$B$2:$B$201,MATCH(I17,Dataset!$A$2:$A$201,0)) -> Robert Anderson | K17: =COUNTIFS(Dataset!$A$2:$A$201,I17) -> 4 | L17: =SUMIFS(Dataset!$E$2:$E$201,Dataset!$A$2:$A$201,I17) -> 4162.44 | M17: =SUMIFS(Dataset!$I$2:$I$201,Dataset!$A$2:$A$201,I17) -> 1605.11 | N17: =RANK(L17,$L$5:$L$34)+COUNTIF($L$5:L17,L17)-1 -> 25 | O17: =IF(L17>=$R$4,"High Value","Standard") -> Standard
A18: South | B18: =COUNTIFS(Dataset!$C$2:$C$201,$A18) -> 42 | C18: =SUMIFS(Dataset!$E$2:$E$201,Dataset!$C$2:$C$201,$A18) -> 40248.79 | D18: =SUMIFS(Dataset!$I$2:$I$201,Dataset!$C$2:$C$201,$A18) -> 13691.91 | E18: =D18/C18 -> 0.3401819 | F18: =AVERAGEIFS(Dataset!$G$2:$G$201,Dataset!$C$2:$C$201,$A18) -> 0.079761905 | I18: CUST014 | J18: =INDEX(Dataset!$B$2:$B$201,MATCH(I18,Dataset!$A$2:$A$201,0)) -> Emma Davis | K18: =COUNTIFS(Dataset!$A$2:$A$201,I18) -> 6 | L18: =SUMIFS(Dataset!$E$2:$E$201,Dataset!$A$2:$A$201,I18) -> 6729.89 | M18: =SUMIFS(Dataset!$I$2:$I$201,Dataset!$A$2:$A$201,I18) -> 2507.18 | N18: =RANK(L18,$L$5:$L$34)+COUNTIF($L$5:L18,L18)-1 -> 12 | O18: =IF(L18>=$R$4,"High Value","Standard") -> Standard
A19: West | B19: =COUNTIFS(Dataset!$C$2:$C$201,$A19) -> 43 | C19: =SUMIFS(Dataset!$E$2:$E$201,Dataset!$C$2:$C$201,$A19) -> 44083.58 | D19: =SUMIFS(Dataset!$I$2:$I$201,Dataset!$C$2:$C$201,$A19) -> 14985.83 | E19: =D19/C19 -> 0.33994131 | F19: =AVERAGEIFS(Dataset!$G$2:$G$201,Dataset!$C$2:$C$201,$A19) -> 0.11162791 | I19: CUST015 | J19: =INDEX(Dataset!$B$2:$B$201,MATCH(I19,Dataset!$A$2:$A$201,0)) -> Linda Taylor | K19: =COUNTIFS(Dataset!$A$2:$A$201,I19) -> 11 | L19: =SUMIFS(Dataset!$E$2:$E$201,Dataset!$A$2:$A$201,I19) -> 11611.06 | M19: =SUMIFS(Dataset!$I$2:$I$201,Dataset!$A$2:$A$201,I19) -> 4201.59 | N19: =RANK(L19,$L$5:$L$34)+COUNTIF($L$5:L19,L19)-1 -> 1 | O19: =IF(L19>=$R$4,"High Value","Standard") -> High Value | Q19: 7. TOP 10 CUSTOMERS BY TOTAL PURCHASE
A20: Total | B20: =SUM(B15:B19) -> 200 | C20: =SUM(C15:C19) -> 195217.76 | D20: =SUM(D15:D19) -> 68287.01 | E20: =D20/C20 -> 0.34979917 | F20: =AVERAGE(Dataset!$G$2:$G$201) -> 0.09725 | I20: CUST016 | J20: =INDEX(Dataset!$B$2:$B$201,MATCH(I20,Dataset!$A$2:$A$201,0)) -> Emma Wilson | K20: =COUNTIFS(Dataset!$A$2:$A$201,I20) -> 4 | L20: =SUMIFS(Dataset!$E$2:$E$201,Dataset!$A$2:$A$201,I20) -> 3369.17 | M20: =SUMIFS(Dataset!$I$2:$I$201,Dataset!$A$2:$A$201,I20) -> 1497.25 | N20: =RANK(L20,$L$5:$L$34)+COUNTIF($L$5:L20,L20)-1 -> 29 | O20: =IF(L20>=$R$4,"High Value","Standard") -> Standard | Q20: Rank | R20: Customer ID | S20: Name (first recorded) | T20: Total Sales | U20: Total Profit
I21: CUST017 | J21: =INDEX(Dataset!$B$2:$B$201,MATCH(I21,Dataset!$A$2:$A$201,0)) -> James Taylor | K21: =COUNTIFS(Dataset!$A$2:$A$201,I21) -> 4 | L21: =SUMIFS(Dataset!$E$2:$E$201,Dataset!$A$2:$A$201,I21) -> 3419.2 | M21: =SUMIFS(Dataset!$I$2:$I$201,Dataset!$A$2:$A$201,I21) -> 1257.21 | N21: =RANK(L21,$L$5:$L$34)+COUNTIF($L$5:L21,L21)-1 -> 28 | O21: =IF(L21>=$R$4,"High Value","Standard") -> Standard | Q21: 1 | R21: =INDEX($I$5:$I$34,MATCH($Q21,$N$5:$N$34,0)) -> CUST015 | S21: =INDEX($J$5:$J$34,MATCH($Q21,$N$5:$N$34,0)) -> Linda Taylor | T21: =INDEX($L$5:$L$34,MATCH($Q21,$N$5:$N$34,0)) -> 11611.06 | U21: =INDEX($M$5:$M$34,MATCH($Q21,$N$5:$N$34,0)) -> 4201.59
I22: CUST018 | J22: =INDEX(Dataset!$B$2:$B$201,MATCH(I22,Dataset!$A$2:$A$201,0)) -> Mary Jackson | K22: =COUNTIFS(Dataset!$A$2:$A$201,I22) -> 5 | L22: =SUMIFS(Dataset!$E$2:$E$201,Dataset!$A$2:$A$201,I22) -> 4951.89 | M22: =SUMIFS(Dataset!$I$2:$I$201,Dataset!$A$2:$A$201,I22) -> 1821.64 | N22: =RANK(L22,$L$5:$L$34)+COUNTIF($L$5:L22,L22)-1 -> 20 | O22: =IF(L22>=$R$4,"High Value","Standard") -> Standard | Q22: 2 | R22: =INDEX($I$5:$I$34,MATCH($Q22,$N$5:$N$34,0)) -> CUST028 | S22: =INDEX($J$5:$J$34,MATCH($Q22,$N$5:$N$34,0)) -> Linda Taylor | T22: =INDEX($L$5:$L$34,MATCH($Q22,$N$5:$N$34,0)) -> 10293.87 | U22: =INDEX($M$5:$M$34,MATCH($Q22,$N$5:$N$34,0)) -> 3541.02
A23: 3. PRODUCT CATEGORY SUMMARY | I23: CUST019 | J23: =INDEX(Dataset!$B$2:$B$201,MATCH(I23,Dataset!$A$2:$A$201,0)) -> James Davis | K23: =COUNTIFS(Dataset!$A$2:$A$201,I23) -> 5 | L23: =SUMIFS(Dataset!$E$2:$E$201,Dataset!$A$2:$A$201,I23) -> 4640.11 | M23: =SUMIFS(Dataset!$I$2:$I$201,Dataset!$A$2:$A$201,I23) -> 1721.12 | N23: =RANK(L23,$L$5:$L$34)+COUNTIF($L$5:L23,L23)-1 -> 21 | O23: =IF(L23>=$R$4,"High Value","Standard") -> Standard | Q23: 3 | R23: =INDEX($I$5:$I$34,MATCH($Q23,$N$5:$N$34,0)) -> CUST007 | S23: =INDEX($J$5:$J$34,MATCH($Q23,$N$5:$N$34,0)) -> Michael Anderson | T23: =INDEX($L$5:$L$34,MATCH($Q23,$N$5:$N$34,0)) -> 9941.88 | U23: =INDEX($M$5:$M$34,MATCH($Q23,$N$5:$N$34,0)) -> 3936.26
A24: Product Category | B24: Orders | C24: Sales | D24: Profit | E24: Profit Margin | F24: Avg Discount | I24: CUST020 | J24: =INDEX(Dataset!$B$2:$B$201,MATCH(I24,Dataset!$A$2:$A$201,0)) -> David Brown | K24: =COUNTIFS(Dataset!$A$2:$A$201,I24) -> 4 | L24: =SUMIFS(Dataset!$E$2:$E$201,Dataset!$A$2:$A$201,I24) -> 4413.71 | M24: =SUMIFS(Dataset!$I$2:$I$201,Dataset!$A$2:$A$201,I24) -> 1664.79 | N24: =RANK(L24,$L$5:$L$34)+COUNTIF($L$5:L24,L24)-1 -> 23 | O24: =IF(L24>=$R$4,"High Value","Standard") -> Standard | Q24: 4 | R24: =INDEX($I$5:$I$34,MATCH($Q24,$N$5:$N$34,0)) -> CUST008 | S24: =INDEX($J$5:$J$34,MATCH($Q24,$N$5:$N$34,0)) -> Robert Anderson | T24: =INDEX($L$5:$L$34,MATCH($Q24,$N$5:$N$34,0)) -> 9760.8 | U24: =INDEX($M$5:$M$34,MATCH($Q24,$N$5:$N$34,0)) -> 3442.48
A25: Books | B25: =COUNTIFS(Dataset!$D$2:$D$201,$A25) -> 49 | C25: =SUMIFS(Dataset!$E$2:$E$201,Dataset!$D$2:$D$201,$A25) -> 47002.46 | D25: =SUMIFS(Dataset!$I$2:$I$201,Dataset!$D$2:$D$201,$A25) -> 16901.63 | E25: =D25/C25 -> 0.35959033 | F25: =AVERAGEIFS(Dataset!$G$2:$G$201,Dataset!$D$2:$D$201,$A25) -> 0.10408163 | I25: CUST021 | J25: =INDEX(Dataset!$B$2:$B$201,MATCH(I25,Dataset!$A$2:$A$201,0)) -> Sarah Anderson | K25: =COUNTIFS(Dataset!$A$2:$A$201,I25) -> 8 | L25: =SUMIFS(Dataset!$E$2:$E$201,Dataset!$A$2:$A$201,I25) -> 8740.18 | M25: =SUMIFS(Dataset!$I$2:$I$201,Dataset!$A$2:$A$201,I25) -> 2848.62 | N25: =RANK(L25,$L$5:$L$34)+COUNTIF($L$5:L25,L25)-1 -> 6 | O25: =IF(L25>=$R$4,"High Value","Standard") -> High Value | Q25: 5 | R25: =INDEX($I$5:$I$34,MATCH($Q25,$N$5:$N$34,0)) -> CUST026 | S25: =INDEX($J$5:$J$34,MATCH($Q25,$N$5:$N$34,0)) -> Mary Davis | T25: =INDEX($L$5:$L$34,MATCH($Q25,$N$5:$N$34,0)) -> 9371.81 | U25: =INDEX($M$5:$M$34,MATCH($Q25,$N$5:$N$34,0)) -> 2922.02
A26: Clothing | B26: =COUNTIFS(Dataset!$D$2:$D$201,$A26) -> 41 | C26: =SUMIFS(Dataset!$E$2:$E$201,Dataset!$D$2:$D$201,$A26) -> 41927.59 | D26: =SUMIFS(Dataset!$I$2:$I$201,Dataset!$D$2:$D$201,$A26) -> 18784.49 | E26: =D26/C26 -> 0.44802217 | F26: =AVERAGEIFS(Dataset!$G$2:$G$201,Dataset!$D$2:$D$201,$A26) -> 0.098780488 | I26: CUST022 | J26: =INDEX(Dataset!$B$2:$B$201,MATCH(I26,Dataset!$A$2:$A$201,0)) -> Robert Anderson | K26: =COUNTIFS(Dataset!$A$2:$A$201,I26) -> 5 | L26: =SUMIFS(Dataset!$E$2:$E$201,Dataset!$A$2:$A$201,I26) -> 4418.28 | M26: =SUMIFS(Dataset!$I$2:$I$201,Dataset!$A$2:$A$201,I26) -> 1605.23 | N26: =RANK(L26,$L$5:$L$34)+COUNTIF($L$5:L26,L26)-1 -> 22 | O26: =IF(L26>=$R$4,"High Value","Standard") -> Standard | Q26: 6 | R26: =INDEX($I$5:$I$34,MATCH($Q26,$N$5:$N$34,0)) -> CUST021 | S26: =INDEX($J$5:$J$34,MATCH($Q26,$N$5:$N$34,0)) -> Sarah Anderson | T26: =INDEX($L$5:$L$34,MATCH($Q26,$N$5:$N$34,0)) -> 8740.18 | U26: =INDEX($M$5:$M$34,MATCH($Q26,$N$5:$N$34,0)) -> 2848.62
A27: Electronics | B27: =COUNTIFS(Dataset!$D$2:$D$201,$A27) -> 43 | C27: =SUMIFS(Dataset!$E$2:$E$201,Dataset!$D$2:$D$201,$A27) -> 41044 | D27: =SUMIFS(Dataset!$I$2:$I$201,Dataset!$D$2:$D$201,$A27) -> 9182.15 | E27: =D27/C27 -> 0.22371479 | F27: =AVERAGEIFS(Dataset!$G$2:$G$201,Dataset!$D$2:$D$201,$A27) -> 0.1 | I27: CUST023 | J27: =INDEX(Dataset!$B$2:$B$201,MATCH(I27,Dataset!$A$2:$A$201,0)) -> Robert Anderson | K27: =COUNTIFS(Dataset!$A$2:$A$201,I27) -> 7 | L27: =SUMIFS(Dataset!$E$2:$E$201,Dataset!$A$2:$A$201,I27) -> 5913.68 | M27: =SUMIFS(Dataset!$I$2:$I$201,Dataset!$A$2:$A$201,I27) -> 2198.62 | N27: =RANK(L27,$L$5:$L$34)+COUNTIF($L$5:L27,L27)-1 -> 18 | O27: =IF(L27>=$R$4,"High Value","Standard") -> Standard | Q27: 7 | R27: =INDEX($I$5:$I$34,MATCH($Q27,$N$5:$N$34,0)) -> CUST003 | S27: =INDEX($J$5:$J$34,MATCH($Q27,$N$5:$N$34,0)) -> Emma Davis | T27: =INDEX($L$5:$L$34,MATCH($Q27,$N$5:$N$34,0)) -> 8490.18 | U27: =INDEX($M$5:$M$34,MATCH($Q27,$N$5:$N$34,0)) -> 2652.75
A28: Furniture | B28: =COUNTIFS(Dataset!$D$2:$D$201,$A28) -> 36 | C28: =SUMIFS(Dataset!$E$2:$E$201,Dataset!$D$2:$D$201,$A28) -> 36612.89 | D28: =SUMIFS(Dataset!$I$2:$I$201,Dataset!$D$2:$D$201,$A28) -> 11579.14 | E28: =D28/C28 -> 0.31625856 | F28: =AVERAGEIFS(Dataset!$G$2:$G$201,Dataset!$D$2:$D$201,$A28) -> 0.097222222 | I28: CUST024 | J28: =INDEX(Dataset!$B$2:$B$201,MATCH(I28,Dataset!$A$2:$A$201,0)) -> David Brown | K28: =COUNTIFS(Dataset!$A$2:$A$201,I28) -> 7 | L28: =SUMIFS(Dataset!$E$2:$E$201,Dataset!$A$2:$A$201,I28) -> 7583.13 | M28: =SUMIFS(Dataset!$I$2:$I$201,Dataset!$A$2:$A$201,I28) -> 2492.1 | N28: =RANK(L28,$L$5:$L$34)+COUNTIF($L$5:L28,L28)-1 -> 11 | O28: =IF(L28>=$R$4,"High Value","Standard") -> Standard | Q28: 8 | R28: =INDEX($I$5:$I$34,MATCH($Q28,$N$5:$N$34,0)) -> CUST012 | S28: =INDEX($J$5:$J$34,MATCH($Q28,$N$5:$N$34,0)) -> Robert Anderson | T28: =INDEX($L$5:$L$34,MATCH($Q28,$N$5:$N$34,0)) -> 8339 | U28: =INDEX($M$5:$M$34,MATCH($Q28,$N$5:$N$34,0)) -> 2988.71
A29: Office Supplies | B29: =COUNTIFS(Dataset!$D$2:$D$201,$A29) -> 31 | C29: =SUMIFS(Dataset!$E$2:$E$201,Dataset!$D$2:$D$201,$A29) -> 28630.82 | D29: =SUMIFS(Dataset!$I$2:$I$201,Dataset!$D$2:$D$201,$A29) -> 11839.6 | E29: =D29/C29 -> 0.4135264 | F29: =AVERAGEIFS(Dataset!$G$2:$G$201,Dataset!$D$2:$D$201,$A29) -> 0.080645161 | I29: CUST025 | J29: =INDEX(Dataset!$B$2:$B$201,MATCH(I29,Dataset!$A$2:$A$201,0)) -> David Brown | K29: =COUNTIFS(Dataset!$A$2:$A$201,I29) -> 6 | L29: =SUMIFS(Dataset!$E$2:$E$201,Dataset!$A$2:$A$201,I29) -> 6716.52 | M29: =SUMIFS(Dataset!$I$2:$I$201,Dataset!$A$2:$A$201,I29) -> 2327.84 | N29: =RANK(L29,$L$5:$L$34)+COUNTIF($L$5:L29,L29)-1 -> 13 | O29: =IF(L29>=$R$4,"High Value","Standard") -> Standard | Q29: 9 | R29: =INDEX($I$5:$I$34,MATCH($Q29,$N$5:$N$34,0)) -> CUST030 | S29: =INDEX($J$5:$J$34,MATCH($Q29,$N$5:$N$34,0)) -> James Wilson | T29: =INDEX($L$5:$L$34,MATCH($Q29,$N$5:$N$34,0)) -> 7928.71 | U29: =INDEX($M$5:$M$34,MATCH($Q29,$N$5:$N$34,0)) -> 2965.48
A30: Total | B30: =SUM(B25:B29) -> 200 | C30: =SUM(C25:C29) -> 195217.76 | D30: =SUM(D25:D29) -> 68287.01 | E30: =D30/C30 -> 0.34979917 | F30: =AVERAGE(Dataset!$G$2:$G$201) -> 0.09725 | I30: CUST026 | J30: =INDEX(Dataset!$B$2:$B$201,MATCH(I30,Dataset!$A$2:$A$201,0)) -> Mary Davis | K30: =COUNTIFS(Dataset!$A$2:$A$201,I30) -> 9 | L30: =SUMIFS(Dataset!$E$2:$E$201,Dataset!$A$2:$A$201,I30) -> 9371.81 | M30: =SUMIFS(Dataset!$I$2:$I$201,Dataset!$A$2:$A$201,I30) -> 2922.02 | N30: =RANK(L30,$L$5:$L$34)+COUNTIF($L$5:L30,L30)-1 -> 5 | O30: =IF(L30>=$R$4,"High Value","Standard") -> High Value | Q30: 10 | R30: =INDEX($I$5:$I$34,MATCH($Q30,$N$5:$N$34,0)) -> CUST004 | S30: =INDEX($J$5:$J$34,MATCH($Q30,$N$5:$N$34,0)) -> Lisa Thomas | T30: =INDEX($L$5:$L$34,MATCH($Q30,$N$5:$N$34,0)) -> 7813.59 | U30: =INDEX($M$5:$M$34,MATCH($Q30,$N$5:$N$34,0)) -> 3211.82
I31: CUST027 | J31: =INDEX(Dataset!$B$2:$B$201,MATCH(I31,Dataset!$A$2:$A$201,0)) -> Emma Davis | K31: =COUNTIFS(Dataset!$A$2:$A$201,I31) -> 5 | L31: =SUMIFS(Dataset!$E$2:$E$201,Dataset!$A$2:$A$201,I31) -> 3906.04 | M31: =SUMIFS(Dataset!$I$2:$I$201,Dataset!$A$2:$A$201,I31) -> 1240.65 | N31: =RANK(L31,$L$5:$L$34)+COUNTIF($L$5:L31,L31)-1 -> 26 | O31: =IF(L31>=$R$4,"High Value","Standard") -> Standard
I32: CUST028 | J32: =INDEX(Dataset!$B$2:$B$201,MATCH(I32,Dataset!$A$2:$A$201,0)) -> Linda Taylor | K32: =COUNTIFS(Dataset!$A$2:$A$201,I32) -> 12 | L32: =SUMIFS(Dataset!$E$2:$E$201,Dataset!$A$2:$A$201,I32) -> 10293.87 | M32: =SUMIFS(Dataset!$I$2:$I$201,Dataset!$A$2:$A$201,I32) -> 3541.02 | N32: =RANK(L32,$L$5:$L$34)+COUNTIF($L$5:L32,L32)-1 -> 2 | O32: =IF(L32>=$R$4,"High Value","Standard") -> High Value
A33: 4. MONTHLY SALES TREND (with ▲▼ arrows via custom number format) | I33: CUST029 | J33: =INDEX(Dataset!$B$2:$B$201,MATCH(I33,Dataset!$A$2:$A$201,0)) -> David Smith | K33: =COUNTIFS(Dataset!$A$2:$A$201,I33) -> 7 | L33: =SUMIFS(Dataset!$E$2:$E$201,Dataset!$A$2:$A$201,I33) -> 5779.05 | M33: =SUMIFS(Dataset!$I$2:$I$201,Dataset!$A$2:$A$201,I33) -> 1611.66 | N33: =RANK(L33,$L$5:$L$34)+COUNTIF($L$5:L33,L33)-1 -> 19 | O33: =IF(L33>=$R$4,"High Value","Standard") -> Standard
A34: Month | B34: Sales | C34: Profit | D34: Orders | E34: MoM Change (▲▼) | F34: MoM Growth % (▲▼) | I34: CUST030 | J34: =INDEX(Dataset!$B$2:$B$201,MATCH(I34,Dataset!$A$2:$A$201,0)) -> James Wilson | K34: =COUNTIFS(Dataset!$A$2:$A$201,I34) -> 9 | L34: =SUMIFS(Dataset!$E$2:$E$201,Dataset!$A$2:$A$201,I34) -> 7928.71 | M34: =SUMIFS(Dataset!$I$2:$I$201,Dataset!$A$2:$A$201,I34) -> 2965.48 | N34: =RANK(L34,$L$5:$L$34)+COUNTIF($L$5:L34,L34)-1 -> 9 | O34: =IF(L34>=$R$4,"High Value","Standard") -> Standard
A35: =DATE(YEAR(MIN(Dataset!$H$2:$H$201)),MONTH(MIN(Dataset!$H$2:$H$201)),1) -> 45383 | B35: =SUMIFS(Dataset!$E$2:$E$201,Dataset!$P$2:$P$201,A35) -> 19029.96 | C35: =SUMIFS(Dataset!$I$2:$I$201,Dataset!$P$2:$P$201,A35) -> 6244.01 | D35: =COUNTIFS(Dataset!$P$2:$P$201,A35) -> 19 | E35: ="" | F35: ="" | I35: Total | K35: =SUM(K5:K34) -> 200 | L35: =SUM(L5:L34) -> 195217.76 | M35: =SUM(M5:M34) -> 68287.01
A36: =EDATE(A35,1) -> 45413 | B36: =SUMIFS(Dataset!$E$2:$E$201,Dataset!$P$2:$P$201,A36) -> 18507.34 | C36: =SUMIFS(Dataset!$I$2:$I$201,Dataset!$P$2:$P$201,A36) -> 6121.35 | D36: =COUNTIFS(Dataset!$P$2:$P$201,A36) -> 21 | E36: =B36-B35 -> -522.62 | F36: =(B36-B35)/B35 -> -0.027463011
A37: =EDATE(A36,1) -> 45444 | B37: =SUMIFS(Dataset!$E$2:$E$201,Dataset!$P$2:$P$201,A37) -> 20187.51 | C37: =SUMIFS(Dataset!$I$2:$I$201,Dataset!$P$2:$P$201,A37) -> 6918 | D37: =COUNTIFS(Dataset!$P$2:$P$201,A37) -> 20 | E37: =B37-B36 -> 1680.17 | F37: =(B37-B36)/B36 -> 0.090783981
A38: =EDATE(A37,1) -> 45474 | B38: =SUMIFS(Dataset!$E$2:$E$201,Dataset!$P$2:$P$201,A38) -> 11609.04 | C38: =SUMIFS(Dataset!$I$2:$I$201,Dataset!$P$2:$P$201,A38) -> 3743.85 | D38: =COUNTIFS(Dataset!$P$2:$P$201,A38) -> 12 | E38: =B38-B37 -> -8578.47 | F38: =(B38-B37)/B37 -> -0.42493948
A39: =EDATE(A38,1) -> 45505 | B39: =SUMIFS(Dataset!$E$2:$E$201,Dataset!$P$2:$P$201,A39) -> 10091.7 | C39: =SUMIFS(Dataset!$I$2:$I$201,Dataset!$P$2:$P$201,A39) -> 3302.84 | D39: =COUNTIFS(Dataset!$P$2:$P$201,A39) -> 10 | E39: =B39-B38 -> -1517.34 | F39: =(B39-B38)/B38 -> -0.13070331
A40: =EDATE(A39,1) -> 45536 | B40: =SUMIFS(Dataset!$E$2:$E$201,Dataset!$P$2:$P$201,A40) -> 20533.5 | C40: =SUMIFS(Dataset!$I$2:$I$201,Dataset!$P$2:$P$201,A40) -> 7457.52 | D40: =COUNTIFS(Dataset!$P$2:$P$201,A40) -> 20 | E40: =B40-B39 -> 10441.8 | F40: =(B40-B39)/B39 -> 1.0346919
A41: =EDATE(A40,1) -> 45566 | B41: =SUMIFS(Dataset!$E$2:$E$201,Dataset!$P$2:$P$201,A41) -> 14215.24 | C41: =SUMIFS(Dataset!$I$2:$I$201,Dataset!$P$2:$P$201,A41) -> 4861.7 | D41: =COUNTIFS(Dataset!$P$2:$P$201,A41) -> 14 | E41: =B41-B40 -> -6318.26 | F41: =(B41-B40)/B40 -> -0.30770497
...

Sheet Dashboard
B2: SALES ANALYTICS DASHBOARD
B3: ="Orders from "&TEXT(MIN(Dataset!$H$2:$H$201),"dd-mmm-yyyy")&" to "&TEXT(MAX(Dataset!$H$2:$H$201),"dd-mmm-yyyy")&" | "&TEXT(COUNT(Dataset!$E$2:$E$201),"0")&" orders | Refreshed "&TEXT(NOW(),"dd-mmm-yyyy hh:mm") -> Orders from 10-Apr-2024 to 07-Apr-2025 | 200 orders | Refreshed 09-Oct-2026 15:21
B5: TOTAL SALES | E5: TOTAL PROFIT | H5: PROFIT MARGIN | L5: TOTAL ORDERS | O5: AVG ORDER VALUE | R5: HIGH-VALUE CUSTOMERS
B6: ='Pivot Table'!C20 -> 195217.76 | E6: ='Pivot Table'!D20 -> 68287.01 | H6: ='Pivot Table'!E20 -> 0.34979917 | L6: ='Pivot Table'!B20 -> 200 | O6: ='Pivot Table'!C20/'Pivot Table'!B20 -> 976.0888 | R6: ='Pivot Table'!R5 -> 8
B8: AVG DISCOUNT | E8: LATEST MoM SALES GROWTH | H8: TOP REGION | L8: TOP PRODUCT CATEGORY | O8: PROFIT vs SALES R² | R8: TOP 10 CUSTOMER SHARE
B9: ='Pivot Table'!F20 -> 0.09725 | E9: ='Pivot Table'!F47 -> -0.81806117 | H9: =INDEX('Pivot Table'!A15:A19,MATCH(MAX('Pivot Table'!C15:C19),'Pivot Table'!C15:C19,0)) -> West | L9: =INDEX('Pivot Table'!A25:A29,MATCH(MAX('Pivot Table'!C25:C29),'Pivot Table'!C25:C29,0)) -> Books | O9: =Dataset!U65 -> 0.5981523 | R9: =SUM('Pivot Table'!T21:T30)/'Pivot Table'!C20 -> 0.47275965
B10: CHARTS – Bar · Pie · Line
B62: KEY INSIGHTS (Data Storytelling)
B63: ="1. Overview: "&TEXT('Pivot Table'!C20,"#,##0")&" in sales and "&TEXT('Pivot Table'!D20,"#,##0")&" in profit from "&'Pivot Table'!B20&" orders – an overall profit margin of "&TEXT('Pivot Table'!E20,"0.0%")&"." -> 1. Overview: 1,95,218 in sales and 68,287 in profit from 200 orders – an overall profit margin of 35.0%.
B64: ="2. Regions: "&INDEX('Pivot Table'!$A$15:$A$19,MATCH(MAX('Pivot Table'!$C$15:$C$19),'Pivot Table'!$C$15:$C$19,0))&" leads with "&TEXT(MAX('Pivot Table'!$C$15:$C$19),"#,##0")&" ("&TEXT(MAX('Pivot Table'!$C$15:$C$19)/'Pivot Table'!C20,"0.0%")&" of sales); "&INDEX('Pivot Table'!$A$15:$A$19,MATCH(MIN('Pivot Table'!$C$15:$C$19),'Pivot Table'!$C$15:$C$19,0))&" is lowest at "&TEXT(MIN('Pivot Table'!$C$15:$C$19),"#,##0")&"." -> 2. Regions: West leads with 44,084 (22.6% of sales); East is lowest at 32,442.
B65: ="3. Products: "&INDEX('Pivot Table'!$A$25:$A$29,MATCH(MAX('Pivot Table'!$C$25:$C$29),'Pivot Table'!$C$25:$C$29,0))&" is the top category ("&TEXT(MAX('Pivot Table'!$C$25:$C$29)/'Pivot Table'!C20,"0.0%")&" of sales); "&INDEX('Pivot Table'!$A$25:$A$29,MATCH(MIN('Pivot Table'!$C$25:$C$29),'Pivot Table'!$C$25:$C$29,0))&" contributes the least ("&TEXT(MIN('Pivot Table'!$C$25:$C$29)/'Pivot Table'!C20,"0.0%")&")." -> 3. Products: Books is the top category (24.1% of sales); Office Supplies contributes the least (14.7%).
B66: ="4. Trend: best month was "&TEXT(INDEX('Pivot Table'!A35:A47,MATCH(MAX('Pivot Table'!B35:B47),'Pivot Table'!B35:B47,0)),"mmm-yyyy")&" ("&TEXT(MAX('Pivot Table'!B35:B47),"#,##0")&"); weakest was "&TEXT(INDEX('Pivot Table'!A35:A47,MATCH(MIN('Pivot Table'!B35:B47),'Pivot Table'!B35:B47,0)),"mmm-yyyy")&" ("&TEXT(MIN('Pivot Table'!B35:B47),"#,##0")&"). The last month holds only part of a month, so its growth is understated." -> 4. Trend: best month was Sep-2024 (20,534); weakest was Apr-2025 (3,212). The last month holds only part of a month, so its growth is understated.
B67: ="5. Customers: the top 10 customers generate "&TEXT(SUM('Pivot Table'!T21:T30)/'Pivot Table'!C20,"0.0%")&" of sales, and "&'Pivot Table'!R5&" customers meet the high-value threshold of "&TEXT('Pivot Table'!R4,"#,##0")&"." -> 5. Customers: the top 10 customers generate 47.3% of sales, and 8 customers meet the high-value threshold of 8,236.
B68: ="6. Regression (ToolPak): every extra 1.00 of sales adds about "&TEXT(Dataset!U77,"0.00")&" of profit (R² = "&TEXT(Dataset!U65,"0.00")&"), so sales volume explains "&TEXT(Dataset!U65,"0%")&" of the variation in profit." -> 6. Regression (ToolPak): every extra 1.00 of sales adds about 0.35 of profit (R² = 0.60), so sales volume explains 60% of the variation in profit.
B69: ="7. What-if: a flat "&TEXT(Dataset!U3,"0%")&" discount would move total profit by "&TEXT(Dataset!W8,"#,##0;-#,##0")&" ("&TEXT(Dataset!X8,"0.0%;-0.0%")&"); hitting a profit target of "&TEXT(Dataset!U11,"#,##0")&" needs a discount of about "&IF(ISNUMBER(Dataset!U12),TEXT(Dataset!U12,"0.0%"),"– (not achievable)")&"." -> 7. What-if: a flat 10% discount would move total profit by 1,007 (1.5%); hitting a profit target of 80,000 needs a discount of about 5.1%.
